#The try block will generate an exception, because x is not defined
try:
    print(x)
except:
    print("An Exception Occured")